Workbook

Sheet Evaluación
A1: CIBERPROTECCIÓN PARA PyMES · Capítulo 14 — Disposición Final
A2: Evaluación para la Acreditación de Proveedores de Destrucción y Borrado Seguro
A3: DATOS DEL PROVEEDOR EVALUADO
A4: Razón social | D4: ID tributario (NIT/RUC/RFC)
A5: Servicio evaluado | D5: Modalidad
A6: Contacto del proveedor | D6: Sensibilidad de la información
A7: Evaluador | D7: Fecha de evaluación
A9: Bloque | B9: N° | C9: Criterio de acreditación | D9: Tipo | E9: Cumple | F9: Evidencia verificada | G9: Observaciones
A10: CERTIFICACIONES | B10: 1 | C10: Cuenta con al menos una certificación vigente reconocida en la industria de destrucción de datos: NAID AAA, R2 o e-Stewards. | D10: Obligatorio | E10: Sin evaluar
B11: 2 | C11: La vigencia de la certificación fue confirmada en el registro público del organismo certificador, no únicamente en la copia entregada por el proveedor. | D11: Obligatorio | E11: Sin evaluar
B12: 3 | C12: El alcance de la certificación cubre el servicio contratado (destrucción física, borrado lógico) y la modalidad (en sitio o en planta). | D12: Obligatorio | E12: Sin evaluar
B13: 4 | C13: El alcance de la certificación cubre la instalación física donde se procesarán los dispositivos de la organización. | D13: Obligatorio | E13: Sin evaluar
B14: 5 | C14: La certificación cubre los tipos de medio que se entregarán (discos HDD, SSD, memorias flash, teléfonos móviles, cintas). | D14: Complementario | E14: Sin evaluar
A15: CERTIFICADOS DE DESTRUCCIÓN | B15: 6 | C15: Emite un certificado de destrucción o borrado individualizado por dispositivo, identificado por número de serie. | D15: Obligatorio | E15: Sin evaluar
B16: 7 | C16: El certificado registra el método aplicado (limpiar, purgar o destruir), la técnica, la herramienta y su versión, el resultado de la verificación, la fecha y la firma del responsable. | D16: Obligatorio | E16: Sin evaluar
B17: 8 | C17: Se revisó un certificado de muestra emitido a otro cliente (con datos anonimizados) y cumple con los campos requeridos. | D17: Obligatorio | E17: Sin evaluar
B18: 9 | C18: El plazo máximo de entrega de los certificados tras la ejecución del servicio está definido por escrito. | D18: Complementario | E18: Sin evaluar
B19: 10 | C19: Los certificados son verificables en un portal del proveedor o mediante firma digital. | D19: Complementario | E19: Sin evaluar
B20: 11 | C20: Para destrucción física, declara el tamaño máximo de partícula resultante según el tipo de medio. | D20: Complementario | E20: Sin evaluar
A21: AUDITORÍA Y VERIFICACIÓN | B21: 12 | C21: Acepta por escrito auditorías o visitas de verificación por parte de la organización o de un tercero designado. | D21: Obligatorio | E21: Sin evaluar
B22: 13 | C22: Se realizó una visita de verificación a las instalaciones del proveedor (obligatoria cuando la sensibilidad de la información es Alta). | D22: =IF($F$6="Alta","Obligatorio","Complementario") -> Complementario | E22: Sin evaluar
B23: 14 | C23: Permite presenciar la destrucción, en sitio o mediante transmisión de video. | D23: Complementario | E23: Sin evaluar
B24: 15 | C24: Entrega evidencia fotográfica o en video de la destrucción, vinculada a los números de serie. | D24: Complementario | E24: Sin evaluar
B25: 16 | C25: Presentó el informe de la última auditoría del organismo certificador sin hallazgos críticos abiertos. | D25: Complementario | E25: Sin evaluar
A26: CADENA DE CUSTODIA | B26: 17 | C26: Dispone de un procedimiento documentado de cadena de custodia desde el retiro del dispositivo hasta su destrucción. | D26: Obligatorio | E26: Sin evaluar
B27: 18 | C27: Concilia el inventario por número de serie al momento del retiro y firma el acta de entrega correspondiente. | D27: Obligatorio | E27: Sin evaluar
B28: 19 | C28: Transporta los dispositivos en contenedores cerrados con sello de seguridad y en vehículos con seguimiento satelital. | D28: Complementario | E28: Sin evaluar
B29: 20 | C29: El personal que manipula los dispositivos cuenta con verificación de antecedentes. | D29: Complementario | E29: Sin evaluar
B30: 21 | C30: Define un plazo máximo entre el retiro de los dispositivos y su destrucción o borrado. | D30: Complementario | E30: Sin evaluar
A31: CONDICIONES CONTRACTUALES | B31: 22 | C31: El contrato incluye una cláusula de confidencialidad sobre la información contenida en los dispositivos. | D31: Obligatorio | E31: Sin evaluar
B32: 23 | C32: El contrato prohíbe la subcontratación del servicio sin autorización previa y escrita de la organización. | D32: Obligatorio | E32: Sin evaluar
B33: 24 | C33: El contrato obliga a notificar la pérdida o sustracción de un dispositivo en custodia dentro de un plazo definido. | D33: Obligatorio | E33: Sin evaluar
B34: 25 | C34: Mantiene una póliza de responsabilidad civil que cubre incidentes derivados del servicio. | D34: Complementario | E34: Sin evaluar
B35: 26 | C35: Dispone de los residuos conforme a la normativa local de residuos de aparatos eléctricos y electrónicos (RAEE). | D35: Complementario | E35: Sin evaluar
A37: RESULTADO DE LA EVALUACIÓN
A38: Criterios obligatorios | D38: =COUNTIF($D$10:$D$35,"Obligatorio") -> 13
A39: Obligatorios que cumplen | D39: =COUNTIFS($D$10:$D$35,"Obligatorio",$E$10:$E$35,"Sí")+COUNTIFS($D$10:$D$35,"Obligatorio",$E$10:$E$35,"No aplica") -> 0
A40: Obligatorios con incumplimiento (No / Parcial) | D40: =COUNTIFS($D$10:$D$35,"Obligatorio",$E$10:$E$35,"No")+COUNTIFS($D$10:$D$35,"Obligatorio",$E$10:$E$35,"Parcial") -> 0
A41: Obligatorios sin evaluar | D41: =COUNTIFS($D$10:$D$35,"Obligatorio",$E$10:$E$35,"Sin evaluar") -> 13
A42: Cumplimiento de criterios complementarios | D42: =IFERROR(COUNTIFS($D$10:$D$35,"Complementario",$E$10:$E$35,"Sí")/(COUNTIF($D$10:$D$35,"Complementario")-COUNTIFS($D$10:$D$35,"Complementario",$E$10:$E$35,"No aplica")),0) -> 0
...

Sheet Proveedores Autorizados
A1: CIBERPROTECCIÓN PARA PyMES · Capítulo 14 — Disposición Final
A2: Listado de Proveedores Autorizados de Destrucción y Borrado Seguro
A3: ID | B3: Razón social | C3: ID tributario | D3: Servicio | E3: Vigencia NAID AAA | F3: Vigencia R2 | G3: Vigencia e-Stewards | H3: Certificado por dispositivo | I3: Permite auditoría | J3: Fecha de acreditación | K3: Próxima reevaluación | L3: Estado | M3: Alerta de certificación | N3: Alerta de reevaluación | O3: ¿Apto para recibir dispositivos? | P3: Responsable interno | Q3: Observaciones
A4: PRV-01 | B4: Destrucción Segura Andina S.A.S. (ejemplo) | C4: 900.123.456-7 | D4: Destrucción física y borrado lógico | E4: 46446 | F4: 46356 | H4: Sí | I4: Sí | J4: 46096 | K4: =IF(J4="","",EDATE(J4,12)) -> 46461 | L4: Autorizado | M4: =IF(B4="","",IF(COUNT(E4:G4)=0,"Sin certificación",IF(MIN(E4:G4)<TODAY(),"Certificación vencida",IF(MIN(E4:G4)-TODAY()<=60,"Vence en ≤60 días","Vigente")))) -> Vigente | N4: =IF(OR(B4="",K4=""),"",IF(K4<TODAY(),"Reevaluación vencida",IF(K4-TODAY()<=30,"Vence en ≤30 días","Vigente"))) -> Vigente | O4: =IF(B4="","",IF(AND(L4="Autorizado",H4="Sí",I4="Sí",OR(M4="Vigente",M4="Vence en ≤60 días"),OR(N4="Vigente",N4="Vence en ≤30 días")),"SÍ","NO")) -> SÍ | P4: Jefe de TI | Q4: Fila de ejemplo: reemplazar o eliminar. Visita de verificación realizada el 2026-03-10.
A5: PRV-02 | K5: =IF(J5="","",EDATE(J5,12)) | M5: =IF(B5="","",IF(COUNT(E5:G5)=0,"Sin certificación",IF(MIN(E5:G5)<TODAY(),"Certificación vencida",IF(MIN(E5:G5)-TODAY()<=60,"Vence en ≤60 días","Vigente")))) | N5: =IF(OR(B5="",K5=""),"",IF(K5<TODAY(),"Reevaluación vencida",IF(K5-TODAY()<=30,"Vence en ≤30 días","Vigente"))) | O5: =IF(B5="","",IF(AND(L5="Autorizado",H5="Sí",I5="Sí",OR(M5="Vigente",M5="Vence en ≤60 días"),OR(N5="Vigente",N5="Vence en ≤30 días")),"SÍ","NO"))
A6: PRV-03 | K6: =IF(J6="","",EDATE(J6,12)) | M6: =IF(B6="","",IF(COUNT(E6:G6)=0,"Sin certificación",IF(MIN(E6:G6)<TODAY(),"Certificación vencida",IF(MIN(E6:G6)-TODAY()<=60,"Vence en ≤60 días","Vigente")))) | N6: =IF(OR(B6="",K6=""),"",IF(K6<TODAY(),"Reevaluación vencida",IF(K6-TODAY()<=30,"Vence en ≤30 días","Vigente"))) | O6: =IF(B6="","",IF(AND(L6="Autorizado",H6="Sí",I6="Sí",OR(M6="Vigente",M6="Vence en ≤60 días"),OR(N6="Vigente",N6="Vence en ≤30 días")),"SÍ","NO"))
A7: PRV-04 | K7: =IF(J7="","",EDATE(J7,12)) | M7: =IF(B7="","",IF(COUNT(E7:G7)=0,"Sin certificación",IF(MIN(E7:G7)<TODAY(),"Certificación vencida",IF(MIN(E7:G7)-TODAY()<=60,"Vence en ≤60 días","Vigente")))) | N7: =IF(OR(B7="",K7=""),"",IF(K7<TODAY(),"Reevaluación vencida",IF(K7-TODAY()<=30,"Vence en ≤30 días","Vigente"))) | O7: =IF(B7="","",IF(AND(L7="Autorizado",H7="Sí",I7="Sí",OR(M7="Vigente",M7="Vence en ≤60 días"),OR(N7="Vigente",N7="Vence en ≤30 días")),"SÍ","NO"))
A8: PRV-05 | K8: =IF(J8="","",EDATE(J8,12)) | M8: =IF(B8="","",IF(COUNT(E8:G8)=0,"Sin certificación",IF(MIN(E8:G8)<TODAY(),"Certificación vencida",IF(MIN(E8:G8)-TODAY()<=60,"Vence en ≤60 días","Vigente")))) | N8: =IF(OR(B8="",K8=""),"",IF(K8<TODAY(),"Reevaluación vencida",IF(K8-TODAY()<=30,"Vence en ≤30 días","Vigente"))) | O8: =IF(B8="","",IF(AND(L8="Autorizado",H8="Sí",I8="Sí",OR(M8="Vigente",M8="Vence en ≤60 días"),OR(N8="Vigente",N8="Vence en ≤30 días")),"SÍ","NO"))
A9: PRV-06 | K9: =IF(J9="","",EDATE(J9,12)) | M9: =IF(B9="","",IF(COUNT(E9:G9)=0,"Sin certificación",IF(MIN(E9:G9)<TODAY(),"Certificación vencida",IF(MIN(E9:G9)-TODAY()<=60,"Vence en ≤60 días","Vigente")))) | N9: =IF(OR(B9="",K9=""),"",IF(K9<TODAY(),"Reevaluación vencida",IF(K9-TODAY()<=30,"Vence en ≤30 días","Vigente"))) | O9: =IF(B9="","",IF(AND(L9="Autorizado",H9="Sí",I9="Sí",OR(M9="Vigente",M9="Vence en ≤60 días"),OR(N9="Vigente",N9="Vence en ≤30 días")),"SÍ","NO"))
A10: PRV-07 | K10: =IF(J10="","",EDATE(J10,12)) | M10: =IF(B10="","",IF(COUNT(E10:G10)=0,"Sin certificación",IF(MIN(E10:G10)<TODAY(),"Certificación vencida",IF(MIN(E10:G10)-TODAY()<=60,"Vence en ≤60 días","Vigente")))) | N10: =IF(OR(B10="",K10=""),"",IF(K10<TODAY(),"Reevaluación vencida",IF(K10-TODAY()<=30,"Vence en ≤30 días","Vigente"))) | O10: =IF(B10="","",IF(AND(L10="Autorizado",H10="Sí",I10="Sí",OR(M10="Vigente",M10="Vence en ≤60 días"),OR(N10="Vigente",N10="Vence en ≤30 días")),"SÍ","NO"))
A11: PRV-08 | K11: =IF(J11="","",EDATE(J11,12)) | M11: =IF(B11="","",IF(COUNT(E11:G11)=0,"Sin certificación",IF(MIN(E11:G11)<TODAY(),"Certificación vencida",IF(MIN(E11:G11)-TODAY()<=60,"Vence en ≤60 días","Vigente")))) | N11: =IF(OR(B11="",K11=""),"",IF(K11<TODAY(),"Reevaluación vencida",IF(K11-TODAY()<=30,"Vence en ≤30 días","Vigente"))) | O11: =IF(B11="","",IF(AND(L11="Autorizado",H11="Sí",I11="Sí",OR(M11="Vigente",M11="Vence en ≤60 días"),OR(N11="Vigente",N11="Vence en ≤30 días")),"SÍ","NO"))
A12: PRV-09 | K12: =IF(J12="","",EDATE(J12,12)) | M12: =IF(B12="","",IF(COUNT(E12:G12)=0,"Sin certificación",IF(MIN(E12:G12)<TODAY(),"Certificación vencida",IF(MIN(E12:G12)-TODAY()<=60,"Vence en ≤60 días","Vigente")))) | N12: =IF(OR(B12="",K12=""),"",IF(K12<TODAY(),"Reevaluación vencida",IF(K12-TODAY()<=30,"Vence en ≤30 días","Vigente"))) | O12: =IF(B12="","",IF(AND(L12="Autorizado",H12="Sí",I12="Sí",OR(M12="Vigente",M12="Vence en ≤60 días"),OR(N12="Vigente",N12="Vence en ≤30 días")),"SÍ","NO"))
A13: PRV-10 | K13: =IF(J13="","",EDATE(J13,12)) | M13: =IF(B13="","",IF(COUNT(E13:G13)=0,"Sin certificación",IF(MIN(E13:G13)<TODAY(),"Certificación vencida",IF(MIN(E13:G13)-TODAY()<=60,"Vence en ≤60 días","Vigente")))) | N13: =IF(OR(B13="",K13=""),"",IF(K13<TODAY(),"Reevaluación vencida",IF(K13-TODAY()<=30,"Vence en ≤30 días","Vigente"))) | O13: =IF(B13="","",IF(AND(L13="Autorizado",H13="Sí",I13="Sí",OR(M13="Vigente",M13="Vence en ≤60 días"),OR(N13="Vigente",N13="Vence en ≤30 días")),"SÍ","NO"))
A14: PRV-11 | K14: =IF(J14="","",EDATE(J14,12)) | M14: =IF(B14="","",IF(COUNT(E14:G14)=0,"Sin certificación",IF(MIN(E14:G14)<TODAY(),"Certificación vencida",IF(MIN(E14:G14)-TODAY()<=60,"Vence en ≤60 días","Vigente")))) | N14: =IF(OR(B14="",K14=""),"",IF(K14<TODAY(),"Reevaluación vencida",IF(K14-TODAY()<=30,"Vence en ≤30 días","Vigente"))) | O14: =IF(B14="","",IF(AND(L14="Autorizado",H14="Sí",I14="Sí",OR(M14="Vigente",M14="Vence en ≤60 días"),OR(N14="Vigente",N14="Vence en ≤30 días")),"SÍ","NO"))
A15: PRV-12 | K15: =IF(J15="","",EDATE(J15,12)) | M15: =IF(B15="","",IF(COUNT(E15:G15)=0,"Sin certificación",IF(MIN(E15:G15)<TODAY(),"Certificación vencida",IF(MIN(E15:G15)-TODAY()<=60,"Vence en ≤60 días","Vigente")))) | N15: =IF(OR(B15="",K15=""),"",IF(K15<TODAY(),"Reevaluación vencida",IF(K15-TODAY()<=30,"Vence en ≤30 días","Vigente"))) | O15: =IF(B15="","",IF(AND(L15="Autorizado",H15="Sí",I15="Sí",OR(M15="Vigente",M15="Vence en ≤60 días"),OR(N15="Vigente",N15="Vence en ≤30 días")),"SÍ","NO"))
A16: PRV-13 | K16: =IF(J16="","",EDATE(J16,12)) | M16: =IF(B16="","",IF(COUNT(E16:G16)=0,"Sin certificación",IF(MIN(E16:G16)<TODAY(),"Certificación vencida",IF(MIN(E16:G16)-TODAY()<=60,"Vence en ≤60 días","Vigente")))) | N16: =IF(OR(B16="",K16=""),"",IF(K16<TODAY(),"Reevaluación vencida",IF(K16-TODAY()<=30,"Vence en ≤30 días","Vigente"))) | O16: =IF(B16="","",IF(AND(L16="Autorizado",H16="Sí",I16="Sí",OR(M16="Vigente",M16="Vence en ≤60 días"),OR(N16="Vigente",N16="Vence en ≤30 días")),"SÍ","NO"))
... A33: PRV-30 | K33: =IF(J33="","",EDATE(J33,12)) | M33: =IF(B33="","",IF(COUNT(E33:G33)=0,"Sin certificación",IF(MIN(E33:G33)<TODAY(),"Certificación vencida",IF(MIN(E33:G33)-TODAY()<=60,"Vence en ≤60 días","Vigente")))) | N33: =IF(OR(B33="",K33=""),"",IF(K33<TODAY(),"Reevaluación vencida",IF(K33-TODAY()<=30,"Vence en ≤30 días","Vigente"))) | O33: =IF(B33="","",IF(AND(L33="Autorizado",H33="Sí",I33="Sí",OR(M33="Vigente",M33="Vence en ≤60 días"),OR(N33="Vigente",N33="Vence en ≤30 días")),"SÍ","NO"))
A35: Regla de uso: ningún dispositivo se entrega a un proveedor cuya columna «¿Apto para recibir dispositivos?» indique NO, con independencia de la urgencia o del ahorro ofrecido. Las columnas K, M, N y O se calculan automáticamente.

Sheet Dashboard
A1: CIBERPROTECCIÓN PARA PyMES · Capítulo 14 — Disposición Final
A2: Dashboard — Acreditación y Estado de Proveedores
A3: EVALUACIÓN EN CURSO — Cumplimiento por bloque (hoja Evaluación)
A4: Bloque | B4: Criterios | C4: Sí | D4: Parcial | E4: No | F4: No aplica | G4: Sin evaluar
A5: CERTIFICACIONES | B5: =ROWS(Evaluación!E10:E14) -> 5 | C5: =COUNTIF(Evaluación!E10:E14,"Sí") -> 0 | D5: =COUNTIF(Evaluación!E10:E14,"Parcial") -> 0 | E5: =COUNTIF(Evaluación!E10:E14,"No") -> 0 | F5: =COUNTIF(Evaluación!E10:E14,"No aplica") -> 0 | G5: =COUNTIF(Evaluación!E10:E14,"Sin evaluar") -> 5
A6: CERTIFICADOS DE DESTRUCCIÓN | B6: =ROWS(Evaluación!E15:E20) -> 6 | C6: =COUNTIF(Evaluación!E15:E20,"Sí") -> 0 | D6: =COUNTIF(Evaluación!E15:E20,"Parcial") -> 0 | E6: =COUNTIF(Evaluación!E15:E20,"No") -> 0 | F6: =COUNTIF(Evaluación!E15:E20,"No aplica") -> 0 | G6: =COUNTIF(Evaluación!E15:E20,"Sin evaluar") -> 6
A7: AUDITORÍA Y VERIFICACIÓN | B7: =ROWS(Evaluación!E21:E25) -> 5 | C7: =COUNTIF(Evaluación!E21:E25,"Sí") -> 0 | D7: =COUNTIF(Evaluación!E21:E25,"Parcial") -> 0 | E7: =COUNTIF(Evaluación!E21:E25,"No") -> 0 | F7: =COUNTIF(Evaluación!E21:E25,"No aplica") -> 0 | G7: =COUNTIF(Evaluación!E21:E25,"Sin evaluar") -> 5
A8: CADENA DE CUSTODIA | B8: =ROWS(Evaluación!E26:E30) -> 5 | C8: =COUNTIF(Evaluación!E26:E30,"Sí") -> 0 | D8: =COUNTIF(Evaluación!E26:E30,"Parcial") -> 0 | E8: =COUNTIF(Evaluación!E26:E30,"No") -> 0 | F8: =COUNTIF(Evaluación!E26:E30,"No aplica") -> 0 | G8: =COUNTIF(Evaluación!E26:E30,"Sin evaluar") -> 5
A9: CONDICIONES CONTRACTUALES | B9: =ROWS(Evaluación!E31:E35) -> 5 | C9: =COUNTIF(Evaluación!E31:E35,"Sí") -> 0 | D9: =COUNTIF(Evaluación!E31:E35,"Parcial") -> 0 | E9: =COUNTIF(Evaluación!E31:E35,"No") -> 0 | F9: =COUNTIF(Evaluación!E31:E35,"No aplica") -> 0 | G9: =COUNTIF(Evaluación!E31:E35,"Sin evaluar") -> 5
A10: TOTAL | B10: =SUM(B5:B9) -> 26 | C10: =SUM(C5:C9) -> 0 | D10: =SUM(D5:D9) -> 0 | E10: =SUM(E5:E9) -> 0 | F10: =SUM(F5:F9) -> 0 | G10: =SUM(G5:G9) -> 26
A11: Dictamen de la evaluación en curso | D11: =Evaluación!D43 -> EVALUACIÓN INCOMPLETA
A13: LISTADO DE PROVEEDORES — Estado general (hoja Proveedores Autorizados)
A14: Indicador | B14: Cantidad
A15: Proveedores registrados | B15: =COUNTA('Proveedores Autorizados'!B4:B33) -> 1
A16: En evaluación | B16: =COUNTIF('Proveedores Autorizados'!L4:L33,"En evaluación") -> 0
A17: Autorizados | B17: =COUNTIF('Proveedores Autorizados'!L4:L33,"Autorizado") -> 1
A18: Suspendidos | B18: =COUNTIF('Proveedores Autorizados'!L4:L33,"Suspendido") -> 0
A19: Revocados | B19: =COUNTIF('Proveedores Autorizados'!L4:L33,"Revocado") -> 0
A20: Aptos para recibir dispositivos hoy | B20: =COUNTIF('Proveedores Autorizados'!O4:O33,"SÍ") -> 1
A21: Con certificación vencida o sin certificación | B21: =COUNTIF('Proveedores Autorizados'!M4:M33,"Certificación vencida")+COUNTIF('Proveedores Autorizados'!M4:M33,"Sin certificación") -> 0
A22: Con certificación por vencer (≤60 días) | B22: =COUNTIF('Proveedores Autorizados'!M4:M33,"Vence en ≤60 días") -> 0
A23: Con reevaluación vencida | B23: =COUNTIF('Proveedores Autorizados'!N4:N33,"Reevaluación vencida") -> 0
A24: Autorizados que hoy NO son aptos (requieren acción) | B24: =COUNTIFS('Proveedores Autorizados'!L4:L33,"Autorizado",'Proveedores Autorizados'!O4:O33,"NO") -> 0
A26: Nota: este dashboard se actualiza automáticamente. Los datos se registran en las hojas Evaluación y Proveedores Autorizados.

Sheet Instructivo
A1: CIBERPROTECCIÓN PARA PyMES · Capítulo 14 — Disposición Final
A2: Instructivo de Uso de la Plantilla
A3: PROPÓSITO
A4: Campo | B4: Descripción
A5: Objetivo | B5: Verificar la idoneidad de un proveedor externo de destrucción física o borrado seguro antes de incorporarlo al proceso de disposición final, y mantener el listado actualizado de proveedores autorizados.
A6: Principio | B6: Ningún dispositivo se entrega a un tercero que no haya superado este proceso de acreditación, con independencia de la urgencia o del ahorro que ofrezca.
A7: Celdas editables | B7: Las celdas de fondo amarillo claro en la hoja Evaluación y las columnas A–L, P y Q de la hoja Proveedores Autorizados. Las demás celdas contienen fórmulas y no deben modificarse.
A8: PROCEDIMIENTO
A9: Campo | B9: Descripción
A10: Paso 1 — Datos del proveedor | B10: Completar el bloque «Datos del proveedor evaluado» en la hoja Evaluación. El campo «Sensibilidad de la información» determina si la visita de verificación (criterio 13) es obligatoria: con sensibilidad Alta pasa a ser Obligatorio automáticamente.
A11: Paso 2 — Evaluación de criterios | B11: Asignar a cada criterio un valor en la columna «Cumple» y registrar en «Evidencia verificada» el documento o la verificación que lo respalda (por ejemplo: número de certificado, captura del registro público, acta de visita).
A12: Paso 3 — Dictamen | B12: El dictamen se calcula automáticamente: ACREDITABLE solo si todos los criterios obligatorios están en Sí o No aplica. Un solo criterio obligatorio en No o Parcial produce NO ACREDITABLE.
A13: Paso 4 — Registro | B13: Si el dictamen es ACREDITABLE, registrar al proveedor en la hoja Proveedores Autorizados con estado Autorizado. Guardar una copia de la hoja Evaluación por proveedor como soporte de la decisión.
A14: Paso 5 — Mantenimiento | B14: Revisar mensualmente las columnas de alerta. Suspender al proveedor si su certificación vence o si la reevaluación anual no se realiza a tiempo, y revocarlo ante un incidente o incumplimiento contractual.
A15: HOJA EVALUACIÓN — CAMPOS
A16: Campo | B16: Descripción
A17: Tipo | B17: Obligatorio: su incumplimiento impide la acreditación. Complementario: suma al porcentaje de cumplimiento, pero no bloquea la decisión.
A18: Cumple | B18: Sin evaluar (valor inicial) / Sí / Parcial / No / No aplica. «No aplica» se reserva para criterios que no corresponden al servicio contratado (por ejemplo, tamaño de partícula en un servicio exclusivo de borrado lógico).
A19: Evidencia verificada | B19: Referencia concreta a la evidencia revisada. Una declaración verbal del proveedor no constituye evidencia.
A20: HOJA PROVEEDORES AUTORIZADOS — CAMPOS
A21: Campo | B21: Descripción
A22: Vigencia NAID AAA / R2 / e-Stewards | B22: Fecha de vencimiento de cada certificación que posea el proveedor. Dejar en blanco las que no tenga.
A23: Certificado por dispositivo / Permite auditoría | B23: Sí / No. Ambos deben estar en Sí para que el proveedor resulte apto.
A24: Fecha de acreditación | B24: Fecha del dictamen ACREDITABLE. La próxima reevaluación se calcula a 12 meses.
A25: Estado | B25: En evaluación / Autorizado / Suspendido / Revocado.
A26: Alerta de certificación | B26: Calculada: Sin certificación, Certificación vencida, Vence en ≤60 días o Vigente. Toma la fecha de vencimiento más próxima entre las certificaciones registradas.
A27: Alerta de reevaluación | B27: Calculada: Reevaluación vencida, Vence en ≤30 días o Vigente.
A28: ¿Apto para recibir dispositivos? | B28: Calculada: SÍ únicamente si el estado es Autorizado, emite certificado por dispositivo, permite auditoría y ni la certificación ni la reevaluación están vencidas. Es el campo que debe consultarse antes de cada entrega.
A29: REFERENCIAS
A30: Campo | B30: Descripción
A31: NAID AAA | B31: Certificación de servicios de destrucción de información creada por la National Association for Information Destruction (NAID), administrada actualmente por i-SIGMA.
A32: R2 | B32: Estándar de reciclaje responsable de equipos electrónicos (Responsible Recycling), administrado por SERI; su versión vigente (R2v3) incluye requisitos de saneamiento de datos.
A33: e-Stewards | B33: Estándar de reciclaje y reutilización responsable de equipos electrónicos, administrado por Basel Action Network, con requisitos de seguridad de datos.
A34: NIST SP 800-88 Rev. 2 (sept. 2025) | B34: Guía de saneamiento de medios que define los métodos limpiar, purgar y destruir, y recomienda emitir un certificado de saneamiento por dispositivo.
