Workbook

Sheet Checklist
A1: CIBERPROTECCIÓN PARA PyMES · Capítulo 14 — Disposición Final
A2: Lista de Verificación de Despliegue — Disposición Final
A3: Función | B3: N° | C3: Actividad | D3: Plantilla | E3: Estado | F3: Responsable | G3: Fecha | H3: Observaciones
A4: GOBERNANZA | B4: 1 | C4: Establecer y aprobar la Política de Disposición Final de Activos Tecnológicos | D4: 14.1 | E4: Pendiente
B5: 2 | C5: Definir los roles de autorización, ejecución y verificación, asignados a personas distintas | E5: Pendiente
B6: 3 | C6: Acreditar a los proveedores de destrucción y borrado seguro (NAID AAA, R2 o e-Stewards) | D6: 14.2 | E6: Pendiente
B7: 4 | C7: Mantener actualizado el listado de proveedores autorizados | D7: 14.2 | E7: Pendiente
A8: IDENTIFICACIÓN | B8: 5 | C8: Levantar el inventario de dispositivos pendientes de baja (estado, ubicación y condición) | D8: 14.3 | E8: Pendiente
B9: 6 | C9: Clasificar cada dispositivo según la sensibilidad de la información que contenía (alta, media o baja) | D9: 14.3 | E9: Pendiente
B10: 7 | C10: Actualizar el estado del activo en el inventario corporativo a «inactivo» o «retirado» | E10: Pendiente
A11: PROTECCIÓN | B11: 8 | C11: Preparar la desvinculación: sistemas registrados, respaldo o migración de datos y claves de recuperación del cifrado | D11: 14.4 | E11: Pendiente
B12: 9 | C12: Desvincular el dispositivo del directorio corporativo y de las políticas de acceso condicional | D12: 14.4 | E12: Pendiente
B13: 10 | C13: Revocar certificados digitales, métodos MFA y tokens de sesión asociados al dispositivo | D13: 14.4 | E13: Pendiente
B14: 11 | C14: Cerrar las sesiones activas y liberar las licencias de software asignadas | D14: 14.4 | E14: Pendiente
B15: 12 | C15: Retirar el dispositivo de las consolas UEM, EDR, respaldo y gestión de parches | D15: 14.4 | E15: Pendiente
B16: 13 | C16: Eliminar el dispositivo de los servicios de aprovisionamiento automático y desactivar el bloqueo de activación | D16: 14.4 | E16: Pendiente
B17: 14 | C17: Retirar el dispositivo de la red (ACL, reservas DHCP, NAC) y evaluar la rotación de claves inalámbricas | D17: 14.4 | E17: Pendiente
B18: 15 | C18: Verificar la ausencia de actividad posterior a la desvinculación y autorizar por escrito el paso al borrado | D18: 14.4 | E18: Pendiente
B19: 16 | C19: Seleccionar el método de borrado según el tipo de medio y la sensibilidad (NIST SP 800-88) | E19: Pendiente
B20: 17 | C20: Ejecutar el borrado seguro de equipos de escritorio y portátiles (sobrescritura en HDD, comando de borrado en SSD) | E20: Pendiente
B21: 18 | C21: Procesar de forma individual cada disco de los servidores físicos, incluidos RAID y discos de arranque | E21: Pendiente
B22: 19 | C22: Restablecer los dispositivos móviles y procesar por separado la tarjeta de memoria externa | E22: Pendiente
B23: 20 | C23: Procesar las unidades de almacenamiento independientes: discos externos, memorias USB, tarjetas y cintas | E23: Pendiente
B24: 21 | C24: Destruir físicamente, mediante proveedor certificado, los medios de sensibilidad alta, dañados o no verificables | E24: Pendiente
B25: 22 | C25: Gestionar la baja de servicios cloud y solicitar confirmación escrita de la eliminación definitiva | E25: Pendiente
B26: 23 | C26: Completar el registro del dispositivo con la fecha de ejecución y el número de certificado | D26: 14.3 | E26: Pendiente
B27: 24 | C27: Obtener el certificado individual de borrado o destrucción por número de serie | D27: 14.5 | E27: Pendiente
B28: 25 | C28: Formalizar la entrega al proveedor con acta y cadena de custodia | D28: 14.6 | E28: Pendiente
B29: 26 | C29: Conservar la documentación durante al menos cinco años o el plazo que exija la normativa local | E29: Pendiente
A30: DETECCIÓN | B30: 27 | C30: Auditar periódicamente el cruce entre inventario de activos, registro de bajas e inventario físico de bodega | D30: 14.3 | E30: Pendiente
B31: 28 | C31: Investigar las discrepancias y los dispositivos en situación de baja informal | E31: Pendiente
B32: 29 | C32: Verificar la autenticidad de los certificados y la certificación vigente del proveedor | D32: 14.2 | E32: Pendiente
B33: 30 | C33: Contrastar los números de serie de certificados y registros de borrado con el inventario de activos | E33: Pendiente
B34: 31 | C34: Verificar que ningún dispositivo dado de baja aparezca en la red o en las consolas de gestión remota | E34: Pendiente
A35: RESPUESTA | B35: 32 | C35: Determinar la sensibilidad de la información del dispositivo afectado y escalar a la dirección cuando corresponda | E35: Pendiente
B36: 33 | C36: Intentar recuperar el control del dispositivo ante el proveedor o el receptor | E36: Pendiente
B37: 34 | C37: Documentar el incidente, iniciar el análisis de causa raíz y definir medidas correctivas | D37: 14.3 | E37: Pendiente
A38: RECUPERACIÓN | B38: 35 | C38: Evaluar el alcance de la exposición: información, probabilidad de acceso, impacto y acciones de mitigación | E38: Pendiente
B39: 36 | C39: Notificar a los afectados y reportar a la autoridad de protección de datos cuando la legislación lo exija | E39: Pendiente
B40: 37 | C40: Evaluar la contratación de servicios de monitoreo de identidad para los afectados | E40: Pendiente
...

Sheet Dashboard
A1: CIBERPROTECCIÓN PARA PyMES · Capítulo 14 — Disposición Final
A2: Dashboard — Estado del Despliegue de Disposición Final
A3: Función | B3: Total | C3: Pendiente | D3: En proceso | E3: Completado | F3: No aplica | G3: % Avance
A4: Gobernanza | B4: =COUNTA(Checklist!C4:C7) -> 4 | C4: =COUNTIF(Checklist!E4:E7,"Pendiente") -> 4 | D4: =COUNTIF(Checklist!E4:E7,"En proceso") -> 0 | E4: =COUNTIF(Checklist!E4:E7,"Completado") -> 0 | F4: =COUNTIF(Checklist!E4:E7,"No aplica") -> 0 | G4: =IFERROR(E4/(B4-F4),0) -> 0
A5: Identificación | B5: =COUNTA(Checklist!C8:C10) -> 3 | C5: =COUNTIF(Checklist!E8:E10,"Pendiente") -> 3 | D5: =COUNTIF(Checklist!E8:E10,"En proceso") -> 0 | E5: =COUNTIF(Checklist!E8:E10,"Completado") -> 0 | F5: =COUNTIF(Checklist!E8:E10,"No aplica") -> 0 | G5: =IFERROR(E5/(B5-F5),0) -> 0
A6: Protección | B6: =COUNTA(Checklist!C11:C29) -> 19 | C6: =COUNTIF(Checklist!E11:E29,"Pendiente") -> 19 | D6: =COUNTIF(Checklist!E11:E29,"En proceso") -> 0 | E6: =COUNTIF(Checklist!E11:E29,"Completado") -> 0 | F6: =COUNTIF(Checklist!E11:E29,"No aplica") -> 0 | G6: =IFERROR(E6/(B6-F6),0) -> 0
A7: Detección | B7: =COUNTA(Checklist!C30:C34) -> 5 | C7: =COUNTIF(Checklist!E30:E34,"Pendiente") -> 5 | D7: =COUNTIF(Checklist!E30:E34,"En proceso") -> 0 | E7: =COUNTIF(Checklist!E30:E34,"Completado") -> 0 | F7: =COUNTIF(Checklist!E30:E34,"No aplica") -> 0 | G7: =IFERROR(E7/(B7-F7),0) -> 0
A8: Respuesta | B8: =COUNTA(Checklist!C35:C37) -> 3 | C8: =COUNTIF(Checklist!E35:E37,"Pendiente") -> 3 | D8: =COUNTIF(Checklist!E35:E37,"En proceso") -> 0 | E8: =COUNTIF(Checklist!E35:E37,"Completado") -> 0 | F8: =COUNTIF(Checklist!E35:E37,"No aplica") -> 0 | G8: =IFERROR(E8/(B8-F8),0) -> 0
A9: Recuperación | B9: =COUNTA(Checklist!C38:C42) -> 5 | C9: =COUNTIF(Checklist!E38:E42,"Pendiente") -> 5 | D9: =COUNTIF(Checklist!E38:E42,"En proceso") -> 0 | E9: =COUNTIF(Checklist!E38:E42,"Completado") -> 0 | F9: =COUNTIF(Checklist!E38:E42,"No aplica") -> 0 | G9: =IFERROR(E9/(B9-F9),0) -> 0
A10: TOTAL | B10: =SUM(B4:B9) -> 39 | C10: =SUM(C4:C9) -> 39 | D10: =SUM(D4:D9) -> 0 | E10: =SUM(E4:E9) -> 0 | F10: =SUM(F4:F9) -> 0 | G10: =IFERROR(E10/(B10-F10),0) -> 0
A12: % Avance = Completado / (Total − No aplica)

Sheet Instructivo
A1: CIBERPROTECCIÓN PARA PyMES · Capítulo 14 — Disposición Final
A2: Instructivo de uso
A3: Campo | B3: Descripción
A4: Función | B4: Función del NIST CSF 2.0 a la que pertenece la actividad. Se indica en la primera fila de cada bloque.
A5: N° | B5: Número secuencial de la actividad dentro de la lista.
A6: Actividad | B6: Control o tarea a ejecutar, según lo descrito en el Capítulo 14 — Disposición Final.
A7: Plantilla | B7: Número de la plantilla del capítulo que apoya la actividad, disponible en el repositorio del libro.
A8: Estado | B8: Seleccione en la lista desplegable: Pendiente, En proceso, Completado o No aplica. Use No aplica cuando la actividad no corresponda al entorno de la organización (por ejemplo, si no existen servidores físicos o servicios cloud).
A9: Responsable | B9: Nombre o cargo de la persona encargada. Las actividades de autorización, ejecución y verificación deben recaer en personas distintas.
A10: Fecha | B10: Fecha de ejecución o fecha objetivo. Formato DD/MM/AAAA.
A11: Observaciones | B11: Número de certificado, número de serie, ticket, proveedor u otra información relevante.
A12: Dashboard | B12: Resume automáticamente el estado de las actividades por función y el porcentaje de avance. No requiere edición.
A13: Repositorio | B13: https://github.com/MauricioVergaraMPC/ciberpymes/tree/main/Capitulo_14
