Workbook

Sheet Checklist
A1: CIBERPROTECCIÓN PARA PyMES · Capítulo 7 — Servidores
A2: Lista de Verificación — Segurización de Servidores
A3: Marque el estado de cada control. El Dashboard se actualiza automáticamente.
A4: Servidor: | C4: Responsable: | F4: Fecha:
A5: Función NIST | B5: Subgrupo | C5: N° | D5: Control | E5: Estado | F5: Responsable | G5: Fecha | H5: Observaciones
A6: GOBERNANZA | C6: 1 | D6: Definir la Política de Gestión de Servidores | E6: Pendiente
C7: 2 | D7: Definir estándares de configuración base (hardening baseline) | E7: Pendiente
C8: 3 | D8: Prohibir el uso de herramientas de acceso remoto de terceros en servidores de producción (TeamViewer, AnyDesk, LogMeIn) | E8: Pendiente
C9: 4 | D9: Establecer proceso de gestión de cambios en servidores | E9: Pendiente
A10: IDENTIFICACIÓN | C10: 1 | D10: Levantar listado de servidores (inventario en CMDB) | E10: Pendiente
C11: 2 | D11: Determinar Línea Base de Seguridad por tipo de servidor | E11: Pendiente
C12: 3 | D12: Establecer KRIs de servidores y umbrales de alerta | E12: Pendiente
A13: PROTECCIÓN | B13: Seguridad física | C13: 1 | D13: Segurizar entorno físico (rack cerrado, sala con llave, control de acceso físico) | E13: Pendiente
B14: Red | C14: 2 | D14: Segmentar subredes internas por rol de servidor | E14: Pendiente
B15: Continuidad | C15: 3 | D15: Ejecutar copias de seguridad bare-metal de cada servidor | E15: Pendiente
C16: 4 | D16: Actualizar Sistemas Operativos (parches y versiones en soporte) | E16: Pendiente
C17: 5 | D17: Ejecutar mantenimientos programados (mensual y trimestral) | E17: Pendiente
B18: Hardening — Windows | C18: 6 | D18: Renombrar o deshabilitar la cuenta Administrador por defecto | E18: Pendiente
C19: 7 | D19: Deshabilitar servicios y puertos no requeridos | E19: Pendiente
C20: 8 | D20: Habilitar Windows Defender y configurar exclusiones mínimas | E20: Pendiente
C21: 9 | D21: Configurar Windows Firewall con reglas de entrada restrictivas | E21: Pendiente
C22: 10 | D22: Configurar UAC (Control de Cuentas de Usuario) en nivel máximo | E22: Pendiente
C23: 11 | D23: Implementar Antivirus y mantenerlo actualizado | E23: Pendiente
C24: 12 | D24: Usar Windows LAPS para gestión de contraseñas de administrador local | E24: Pendiente
C25: 13 | D25: Aplicar política de contraseñas y bloqueo de cuentas locales (mínimo 12 caracteres, bloqueo tras 5 intentos fallidos) | E25: Pendiente
C26: 14 | D26: Deshabilitar SMBv1 | E26: Pendiente
C27: 15 | D27: Deshabilitar NetBIOS y LLMNR | E27: Pendiente
C28: 16 | D28: Habilitar auditoría de eventos de seguridad (auditpol / GPO) | E28: Pendiente
C29: 17 | D29: Configurar Windows Update para aplicar parches de seguridad (WSUS) | E29: Pendiente
C30: 18 | D30: Cifrar volúmenes del sistema operativo con BitLocker | E30: Pendiente
... C33: 21 | D33: Verificar configuración con Microsoft Security Compliance Toolkit | E33: Pendiente
B34: Hardening — Linux | C34: 22 | D34: Gestionar usuarios con privilegios de root (sudo; deshabilitar acceso directo root por consola y SSH) | E34: Pendiente
C35: 23 | D35: Deshabilitar servicios y puertos no requeridos | E35: Pendiente
C36: 24 | D36: Configurar SSH: deshabilitar root login, usar autenticación por clave, restringir IPs de origen | E36: Pendiente
C37: 25 | D37: Configurar UFW (Uncomplicated Firewall) o iptables | E37: Pendiente
C38: 26 | D38: Habilitar SELinux o AppArmor en modo enforce | E38: Pendiente
C39: 27 | D39: Implementar Antivirus (ClamAV u equivalente) | E39: Pendiente
C40: 28 | D40: Aplicar política de contraseñas y bloqueo de cuentas (PAM / pam_pwquality y pam_faillock) | E40: Pendiente
C41: 29 | D41: Habilitar actualizaciones automáticas de seguridad (unattended-upgrades / dnf-automatic) | E41: Pendiente
C42: 30 | D42: Instalar y configurar fail2ban | E42: Pendiente
...

Sheet Dashboard
A1: CIBERPROTECCIÓN PARA PyMES · Capítulo 7 — Servidores
A2: Dashboard — Estado de la Lista de Verificación
A3: Actualice los estados en la hoja Checklist. Este panel se recalcula automáticamente.
A4: Función NIST | B4: Total | C4: Pendiente | D4: En progreso | E4: Completado | F4: No aplica | G4: % Completado
A5: GOBERNANZA | B5: 4 | C5: =COUNTIF(Checklist!E6:E9,"Pendiente") -> 4 | D5: =COUNTIF(Checklist!E6:E9,"En progreso") -> 0 | E5: =COUNTIF(Checklist!E6:E9,"Completado") -> 0 | F5: =COUNTIF(Checklist!E6:E9,"No aplica") -> 0 | G5: =IFERROR(E5/B5,0) -> 0
A6: IDENTIFICACIÓN | B6: 3 | C6: =COUNTIF(Checklist!E10:E12,"Pendiente") -> 3 | D6: =COUNTIF(Checklist!E10:E12,"En progreso") -> 0 | E6: =COUNTIF(Checklist!E10:E12,"Completado") -> 0 | F6: =COUNTIF(Checklist!E10:E12,"No aplica") -> 0 | G6: =IFERROR(E6/B6,0) -> 0
A7: PROTECCIÓN | B7: 35 | C7: =COUNTIF(Checklist!E13:E47,"Pendiente") -> 35 | D7: =COUNTIF(Checklist!E13:E47,"En progreso") -> 0 | E7: =COUNTIF(Checklist!E13:E47,"Completado") -> 0 | F7: =COUNTIF(Checklist!E13:E47,"No aplica") -> 0 | G7: =IFERROR(E7/B7,0) -> 0
A8: DETECCIÓN | B8: 4 | C8: =COUNTIF(Checklist!E48:E51,"Pendiente") -> 4 | D8: =COUNTIF(Checklist!E48:E51,"En progreso") -> 0 | E8: =COUNTIF(Checklist!E48:E51,"Completado") -> 0 | F8: =COUNTIF(Checklist!E48:E51,"No aplica") -> 0 | G8: =IFERROR(E8/B8,0) -> 0
A9: RESPUESTA | B9: 3 | C9: =COUNTIF(Checklist!E52:E54,"Pendiente") -> 3 | D9: =COUNTIF(Checklist!E52:E54,"En progreso") -> 0 | E9: =COUNTIF(Checklist!E52:E54,"Completado") -> 0 | F9: =COUNTIF(Checklist!E52:E54,"No aplica") -> 0 | G9: =IFERROR(E9/B9,0) -> 0
A10: RECUPERACIÓN | B10: 3 | C10: =COUNTIF(Checklist!E55:E57,"Pendiente") -> 3 | D10: =COUNTIF(Checklist!E55:E57,"En progreso") -> 0 | E10: =COUNTIF(Checklist!E55:E57,"Completado") -> 0 | F10: =COUNTIF(Checklist!E55:E57,"No aplica") -> 0 | G10: =IFERROR(E10/B10,0) -> 0
A11: TOTAL GENERAL | B11: 52 | C11: =SUM(C5:C10) -> 52 | D11: =SUM(D5:D10) -> 0 | E11: =SUM(E5:E10) -> 0 | F11: =SUM(F5:F10) -> 0 | G11: =SUM(G5:G10) -> 0
A13: Estados: Pendiente · En progreso · Completado · No aplica
